Workbook
Name DATA: Cleaned_data!$A$1:$N$80
Name DATA1: Cleaned_data!$A$1:$O$80

Sheet RAW_DATA
A1: Order ID | B1: Order Date | C1: Ship Date | D1: Customer Name | E1: Segment | F1: City | G1: State | H1: Category | I1: Sub-Category | J1: Sales | K1: Quantity | L1: Discount | M1: Profit | N1: Ship Mode
A2: CA-1001 | B2: 44951 | C2: 44953 | D2: Ankit Jain | E2: Home Office | F2: Bhopal | G2: MP | H2: Office Supplies | I2: Tables | J2: -200 | K2: 5 | L2: 0 | M2: 5446 | N2: First Class
A3: CA-1002 | B3: 44935 | C3: 44941 | D3: Sunil Patil | E3: Corporate | F3: Pune | G3: GJ | H3: Furniture | I3: Phones | J3: 20808 | K3: 2 | L3: 0.1 | M3: -524
A4: CA-1003 | B4: 44928 | C4: 44933 | D4: Neha Singh | E4: Corporate | F4: Ahmedabad | G4: DL | H4: Office Supplies | I4: Chairs | J4: -200 | K4: 3 | L4: 0 | N4: First Class
A5: CA-1004 | B5: 44959 | C5: 44964 | D5: Amit Shah | E5: Home Office | F5: Indore | G5: DL | H5: Furniture | I5: Tables | J5: 44368 | K5: 5 | N5: Standard Class
A6: CA-1005 | B6: 44943 | C6: 44946 | E6: Corporate | F6: Mumbai | G6: MP | H6: Furniture | I6: Laptops | J6: 30679 | K6: 10 | L6: 0.2
A7: CA-1006 | B7: 44943 | C7: 44944 | D7: Ankit Jain | E7: Consumer | F7: Mumbai | H7: Furniture | I7: Laptops | K7: 9 | L7: 0 | N7: Second Class
A8: CA-1007 | B8: 44941 | C8: 44945 | E8: Home Office | F8: Mumbai | G8: GJ | H8: Technology | I8: Tables | J8: 3761 | K8: 5 | L8: 0.2 | M8: -1062
A9: CA-1008 | B9: 44948 | C9: 44954 | D9: Amit Shah | E9: Corporate | G9: GJ | H9: Office Supplies | I9: Chairs | J9: 20756 | K9: 5 | L9: 0.05 | N9: First Class
A10: CA-1009 | B10: 44982 | C10: 44989 | D10: Pooja Mehta | E10: Consumer | F10: Mumbai | H10: Office Supplies | I10: Phones | J10: 41630 | K10: 7 | L10: 0.05 | M10: 6761 | N10: First Class
A11: CA-1010 | B11: 44947 | C11: 44951 | D11: Riya Patel | E11: Corporate | F11: Mumbai | H11: Technology | I11: Binders | J11: 10029 | K11: 9 | L11: 0 | N11: First Class
A12: CA-1011 | B12: 44953 | C12: 44960 | D12: Ankit Jain | E12: Consumer | G12: GJ | H12: Furniture | I12: Tables | J12: -200 | K12: 5 | L12: 0.2 | M12: 3447 | N12: Standard Class
A13: CA-1012 | B13: 44946 | C13: 44948 | D13: Rahul Verma | E13: Home Office | F13: Mumbai | H13: Furniture | I13: Laptops | J13: 44328 | K13: 9 | N13: First Class
A14: CA-1013 | B14: 44929 | E14: Corporate | F14: Mumbai | G14: GJ | H14: Technology | I14: Phones | K14: 1 | L14: 0 | N14: Standard Class
A15: CA-1014 | B15: 44975 | C15: 44981 | D15: Amit Shah | E15: Corporate | F15: Delhi | H15: Office Supplies | I15: Phones | K15: 7 | L15: 0.1 | N15: Second Class
A16: CA-1015 | B16: 44951 | D16: Riya Patel | E16: Consumer | F16: Pune | H16: Furniture | I16: Chairs | J16: -200 | K16: 8 | M16: 3814
A17: CA-1016 | B17: 44971 | C17: 44978 | D17: Pooja Mehta | E17: Consumer | F17: Pune | G17: GJ | H17: Furniture | I17: Chairs | J17: 3756 | K17: 4 | L17: 0.2 | M17: -341
A18: CA-1017 | B18: 44942 | C18: 44947 | D18: Neha Singh | E18: Corporate | F18: Bhopal | G18: GJ | H18: Technology | I18: Phones | K18: 2 | L18: 0.1 | M18: 6242 | N18: First Class
A19: CA-1018 | B19: 44927 | C19: 44934 | D19: Amit Shah | E19: Corporate | F19: Bhopal | G19: MH | H19: Furniture | I19: Tables | J19: -200 | K19: 7 | M19: -1045 | N19: Second Class
A20: CA-1019 | B20: 44960 | C20: 44963 | E20: Corporate | F20: Mumbai | G20: MH | H20: Technology | I20: Binders | J20: 17251 | K20: 8 | L20: 0.2 | N20: Standard Class
A21: CA-1020 | B21: 44959 | C21: 44964 | D21: Neha Singh | E21: Home Office | F21: Delhi | G21: MH | H21: Technology | I21: Phones | K21: 4 | L21: 0
A22: CA-1021 | B22: 44929 | C22: 44935 | D22: Ankit Jain | E22: Home Office | F22: Pune | G22: DL | H22: Technology | I22: Phones | J22: -200 | K22: 6 | L22: 0.2
A23: CA-1022 | B23: 44939 | C23: 44940 | D23: Sunil Patil | E23: Corporate | F23: Ahmedabad | G23: DL | H23: Technology | I23: Binders | J23: 43210 | K23: 2 | L23: 0.2 | N23: First Class
A24: CA-1023 | B24: 44933 | C24: 44940 | D24: Neha Singh | E24: Home Office | F24: Indore | G24: DL | H24: Office Supplies | I24: Phones | J24: 41010 | K24: 7 | L24: 0.2 | M24: 6485 | N24: Second Class
A25: CA-1024 | B25: 44942 | C25: 44944 | D25: Neha Singh | E25: Corporate | F25: Delhi | G25: MH | H25: Technology | I25: Tables | K25: 10 | L25: 0.1 | M25: 4847 | N25: First Class
A26: CA-1025 | B26: 44935 | D26: Rahul Verma | E26: Consumer | G26: GJ | H26: Furniture | I26: Binders | J26: 30689 | K26: 6 | L26: 0.1 | M26: 2921 | N26: Standard Class
A27: CA-1026 | B27: 44946 | C27: 44950 | D27: Riya Patel | E27: Home Office | F27: Mumbai | H27: Technology | I27: Binders | J27: -200 | K27: 2 | L27: 0.2
A28: CA-1027 | B28: 44976 | C28: 44977 | D28: Neha Singh | E28: Corporate | F28: Mumbai | G28: DL | H28: Furniture | I28: Laptops | J28: -200 | K28: 8
A29: CA-1028 | B29: 44945 | C29: 44946 | D29: Rahul Verma | E29: Home Office | F29: Indore | H29: Technology | I29: Storage | J29: 55161 | K29: 2 | N29: Standard Class
A30: CA-1029 | B30: 44982 | C30: 44988 | D30: Sunil Patil | E30: Corporate | G30: MP | H30: Furniture | I30: Laptops | J30: -200 | K30: 9 | L30: 0 | M30: 3429
A31: CA-1030 | B31: 44936 | D31: Sunil Patil | E31: Corporate | F31: Indore | G31: DL | H31: Technology | I31: Binders | J31: -200 | K31: 8 | M31: 4285 | N31: Standard Class
A32: CA-1031 | B32: 44956 | C32: 44962 | D32: Rahul Verma | E32: Corporate | F32: Pune | H32: Office Supplies | I32: Binders | K32: 9 | N32: Standard Class
A33: CA-1032 | B33: 44979 | C33: 44986 | E33: Corporate | F33: Delhi | G33: GJ | H33: Technology | I33: Storage | J33: 35633 | K33: 2
A34: CA-1033 | B34: 44967 | C34: 44969 | D34: Rahul Verma | E34: Consumer | F34: Ahmedabad | G34: GJ | H34: Technology | I34: Tables | J34: -200 | K34: 5 | L34: 0.2
A35: CA-1034 | B35: 44949 | D35: Pooja Mehta | E35: Home Office | F35: Bhopal | G35: MP | H35: Furniture | I35: Phones | J35: -200 | K35: 6 | L35: 0.05
A36: CA-1035 | B36: 44947 | D36: Rahul Verma | E36: Home Office | F36: Mumbai | H36: Office Supplies | I36: Phones | J36: 30387 | K36: 10 | L36: 0.05 | N36: First Class
A37: CA-1036 | B37: 44986 | C37: 44990 | D37: Ankit Jain | E37: Corporate | F37: Delhi | H37: Technology | I37: Storage | J37: -200 | K37: 1
A38: CA-1037 | B38: 44951 | C38: 44957 | D38: Ankit Jain | E38: Corporate | G38: MH | H38: Technology | I38: Phones | K38: 8 | L38: 0.1 | N38: First Class
A39: CA-1038 | B39: 44985 | C39: 44987 | D39: Sunil Patil | E39: Corporate | F39: Bhopal | G39: MP | H39: Office Supplies | I39: Phones | J39: 22479 | K39: 3 | L39: 0.1 | N39: First Class
A40: CA-1039 | B40: 44939 | C40: 44943 | E40: Corporate | F40: Bhopal | G40: GJ | H40: Furniture | I40: Binders | K40: 3 | L40: 0.05
...

Sheet Cleaned_data
A1: Order ID | B1: Order Date | C1: Ship Date | D1: Customer Name | E1: Segment | F1: City | G1: State | H1: Category | I1: Sub-Category | J1: Sales | K1: Quantity | L1: Total_Revenue | M1: Discount | N1: Profit | O1: Delivery Time
A2: CA-1001 | B2: 44951 | C2: 44953 | D2: Ankit Jain | E2: Home Office | F2: Bhopal | G2: MP | H2: Office Supplies | I2: Tables | J2: 200 | K2: 5 | L2: 1000 | M2: 0 | N2: 1000 | O2: =C2-B2 -> 2
A3: CA-1002 | B3: 44935 | C3: 44941 | D3: Sunil Patil | E3: Corporate | F3: Pune | G3: GJ | H3: Furniture | I3: Phones | J3: 20808 | K3: 2 | L3: 41616 | M3: 0.1 | N3: 41615.9 | O3: =C3-B3 -> 6
A4: CA-1003 | B4: 44928 | C4: 44933 | D4: Neha Singh | E4: Corporate | F4: Ahmedabad | G4: DL | H4: Office Supplies | I4: Chairs | J4: 200 | K4: 3 | L4: 600 | M4: 0 | N4: 600 | O4: =C4-B4 -> 5
A5: CA-1004 | B5: 44959 | C5: 44964 | D5: Amit Shah | E5: Home Office | F5: Indore | G5: DL | H5: Furniture | I5: Tables | J5: 44368 | K5: 5 | L5: 221840 | M5: 0 | N5: 221840 | O5: =C5-B5 -> 5
A6: CA-1005 | B6: 44943 | C6: 44946 | D6: Unkown Customer | E6: Corporate | F6: Mumbai | G6: MP | H6: Furniture | I6: Laptops | J6: 30679 | K6: 10 | L6: 306790 | M6: 0.2 | N6: 306789.8 | O6: =C6-B6 -> 3
A7: CA-1006 | B7: 44943 | C7: 44944 | D7: Ankit Jain | E7: Consumer | F7: Mumbai | G7: NA | H7: Furniture | I7: Laptops | J7: 0 | K7: 9 | L7: 0 | M7: 0 | N7: 0 | O7: =C7-B7 -> 1
A8: CA-1007 | B8: 44941 | C8: 44945 | D8: Unkown Customer | E8: Home Office | F8: Mumbai | G8: GJ | H8: Technology | I8: Tables | J8: 3761 | K8: 5 | L8: 18805 | M8: 0.2 | N8: 18804.8 | O8: =C8-B8 -> 4
A9: CA-1008 | B9: 44948 | C9: 44954 | D9: Amit Shah | E9: Corporate | F9: Somewhere | G9: GJ | H9: Office Supplies | I9: Chairs | J9: 20756 | K9: 5 | L9: 103780 | M9: 0.05 | N9: 103779.95 | O9: =C9-B9 -> 6
A10: CA-1009 | B10: 44982 | C10: 44989 | D10: Pooja Mehta | E10: Consumer | F10: Mumbai | G10: NA | H10: Office Supplies | I10: Phones | J10: 41630 | K10: 7 | L10: 291410 | M10: 0.05 | N10: 291409.95 | O10: =C10-B10 -> 7
A11: CA-1010 | B11: 44947 | C11: 44951 | D11: Riya Patel | E11: Corporate | F11: Mumbai | G11: NA | H11: Technology | I11: Binders | J11: 10029 | K11: 9 | L11: 90261 | M11: 0 | N11: 90261 | O11: =C11-B11 -> 4
A12: CA-1011 | B12: 44953 | C12: 44960 | D12: Ankit Jain | E12: Consumer | F12: Somewhere | G12: GJ | H12: Furniture | I12: Tables | J12: 200 | K12: 5 | L12: 1000 | M12: 0.2 | N12: 999.8 | O12: =C12-B12 -> 7
A13: CA-1012 | B13: 44946 | C13: 44948 | D13: Rahul Verma | E13: Home Office | F13: Mumbai | G13: NA | H13: Furniture | I13: Laptops | J13: 44328 | K13: 9 | L13: 398952 | M13: 0 | N13: 398952 | O13: =C13-B13 -> 2
... A80: CA-1100 | B80: 44978 | C80: 44984 | D80: Sunil Patil | E80: Home Office | F80: Indore | G80: NA | H80: Technology | I80: Laptops | J80: 200 | K80: 1 | L80: 200 | M80: 0.2 | N80: 199.8 | O80: =C80-B80 -> 6

Sheet SALES & REVENUE INSIGHTS
A1: What is the total revenue and total profit overall?
A3: Total revenue | C3: Total Profit
A4: =SUM(Cleaned_data!L2:L80) -> 4153970 | C4: =SUM(Cleaned_data!N2:N80) -> 4153964.7
A6: Which category generates the highest total revenue?
A8: Row Labels | B8: Sum of Total_Revenue
A9: Furniture | B9: 1592165
A10: Office Supplies | B10: 1067610
A11: Technology | B11: 1494195
A12: Grand Total | B12: 4153970
A14: Which sub-category is the least profitable?
A16: Row Labels | B16: Sum of Profit
A17: Storage | B17: 0.085228818
A18: Tables | B18: 0.1165041
A19: Binders | B19: 0.11664006
A20: Chairs | B20: 0.18466078
A21: Laptops | B21: 0.22744571
A22: Phones | B22: 0.26952054
A23: Grand Total | B23: 1
A25: What is the average sales value per order?
A27: CA-1022 | B27: =AVERAGEIF(Cleaned_data!A2:A80,'SALES & REVENUE INSIGHTS'!A27,Cleaned_data!J2:J80) -> 43210
A29: Which city contributes the maximum revenue?
A31: Bhopal | B31: =SUMIF(Cleaned_data!F2:F80,'SALES & REVENUE INSIGHTS'!A31,Cleaned_data!L2:L80) -> 171412
A32: Pune | B32: =SUMIF(Cleaned_data!F3:F81,'SALES & REVENUE INSIGHTS'!A32,Cleaned_data!L3:L81) -> 542415
A33: Ahmedabad | B33: =SUMIF(Cleaned_data!F4:F82,'SALES & REVENUE INSIGHTS'!A33,Cleaned_data!L4:L82) -> 388777
A34: Indore | B34: =SUMIF(Cleaned_data!F5:F83,'SALES & REVENUE INSIGHTS'!A34,Cleaned_data!L5:L83) -> 622232
A35: Mumbai | B35: =SUMIF(Cleaned_data!F6:F84,'SALES & REVENUE INSIGHTS'!A35,Cleaned_data!L6:L84) -> 1778834
A36: Somewhere | B36: =SUMIF(Cleaned_data!F7:F85,'SALES & REVENUE INSIGHTS'!A36,Cleaned_data!L7:L85) -> 578834
A37: Delhi | B37: =SUMIF(Cleaned_data!F8:F86,'SALES & REVENUE INSIGHTS'!A37,Cleaned_data!L8:L86) -> 71466
A39: Which state has high sales but low profit?
A41: Row Labels | B41: Sum of Sales | C41: Sum of Profit
A42: GJ | B42: 122109 | C42: 424158.3
A43: MP | B43: 129576 | C43: 511601.2
A44: DL | B44: 181546 | C44: 909410.05
A45: NA | B45: 241655 | C45: 1120291.2
A46: MH | B46: 158986 | C46: 1188504
A47: Grand Total | B47: 833872 | C47: 4153964.7

Sheet PROFITABILITY INSIGHTS
A1: Which category has the highest profit margin?
A3: Row Labels | B3: Profit Marzine
A4: Furniture | B4: 0.38328769
A5: Technology | B5: 0.35970278
A6: Office Supplies | B6: 0.25700953
A7: Grand Total | B7: 1
A9: Are there any orders with negative profit? Why?
A11: Row Labels | B11: Min of Profit
A12: CA-1001 | B12: 1000
A13: CA-1002 | B13: 41615.9
A14: CA-1003 | B14: 600
A15: CA-1004 | B15: 221840
A16: CA-1005 | B16: 306789.8
A17: CA-1006 | B17: 0
A18: CA-1007 | B18: 18804.8
A19: CA-1008 | B19: 103779.95
A20: CA-1009 | B20: 291409.95
A21: CA-1010 | B21: 90261
A22: CA-1011 | B22: 999.8
A23: CA-1012 | B23: 398952
... A91: Grand Total | B91: -0.1
A93: Here are the order ID with the negative profit there is no sale for that specifics order ID and stlll the discount has been calculated for that
A97: Which city has the highest average profit?
A99: Row Labels | B99: Average of Profit
A100: Ahmedabad | B100: 48597.019
A101: Bhopal | B101: 17141.15
A102: Delhi | B102: 10209.379
A103: Indore | B103: 69136.828
A104: Mumbai | B104: 77340.541
A105: Pune | B105: 49310.382
A106: Somewhere | B106: 52621.209
A107: Grand Total | B107: 52581.832

Sheet DISCOUNT ANALYSIS
A1: How does discount impact profit?
A3: Row Labels | B3: Sum of Total_Revenue | C3: Sum of Discount | D3: Sum of Profit
A4: Binders | B4: 0.11664023 | C4: 0.24528302 | D4: 0.11664006
A5: Chairs | B5: 0.1846607 | C5: 0.12264151 | D5: 0.18466078
A6: Laptops | B6: 0.22744555 | C6: 0.10377358 | D6: 0.22744571
A7: Phones | B7: 0.26952048 | C7: 0.22641509 | D7: 0.26952054
A8: Storage | B8: 0.085228829 | C8: 0.094339623 | D8: 0.085228818
A9: Tables | B9: 0.11650421 | C9: 0.20754717 | D9: 0.1165041
A10: Grand Total | B10: 1 | C10: 1 | D10: 1
A12: The above indicated the cat where the discount is more the profit is compartively is less
A14: Which categories receive the highest average discount?
A16: Sub-Category | B16: Hieghest_Avg_Disc
A17: Tables | B17: =AVERAGEIF(Cleaned_data!I2:I80,'DISCOUNT ANALYSIS'!A17,Cleaned_data!M2:M80) -> 0.084615385
A18: Phones | B18: =AVERAGEIF(Cleaned_data!I3:I81,'DISCOUNT ANALYSIS'!A18,Cleaned_data!M3:M81) -> 0.075
A19: Chairs | B19: =AVERAGEIF(Cleaned_data!I4:I82,'DISCOUNT ANALYSIS'!A19,Cleaned_data!M4:M82) -> 0.065
A20: Laptops | B20: =AVERAGEIF(Cleaned_data!I5:I83,'DISCOUNT ANALYSIS'!A20,Cleaned_data!M5:M83) -> 0.05
A21: Binders | B21: =AVERAGEIF(Cleaned_data!I6:I84,'DISCOUNT ANALYSIS'!A21,Cleaned_data!M6:M84) -> 0.072222222
A22: Storage | B22: =AVERAGEIF(Cleaned_data!I7:I85,'DISCOUNT ANALYSIS'!A22,Cleaned_data!M7:M85) -> 0.045454545
A24: Are high discounts leading to higher sales volume?
A26: Row Labels | B26: Sum of Discount | C26: Sum of Sales
A27: Technology | B27: 0.44339623 | C27: 396741
A28: Furniture | B28: 0.27358491 | C28: 229225
A29: Office Supplies | B29: 0.28301887 | C29: 207906
A30: Grand Total | B30: 1 | C30: 833872
A32: Yes we can say that the sale of the cat is more where the discount is more
A34: Which sub-category is most sensitive to discounts?
A36: Row Labels | B36: Sum of Discount
A37: Storage | B37: 0.094339623
A38: Laptops | B38: 0.10377358
A39: Chairs | B39: 0.12264151
A40: Tables | B40: 0.20754717
A41: Phones | B41: 0.22641509
A42: Binders | B42: 0.24528302
A43: Grand Total | B43: 1

Sheet SHIPPING & OPERATIONAL INSIGHTS
A1: What is the average delivery time (Ship Date – Order Date)?
A3: Row Labels | B3: Average of Delivery Time
A4: CA-1047 | B4: 7
A5: CA-1088 | B5: 7
A6: CA-1067 | B6: 7
A7: CA-1009 | B7: 7
A8: CA-1032 | B8: 7
A9: CA-1011 | B9: 7
A10: CA-1050 | B10: 7
A11: CA-1016 | B11: 7
A12: CA-1018 | B12: 7
A13: CA-1023 | B13: 7
A14: CA-1014 | B14: 6
A15: CA-1008 | B15: 6
... A83: Grand Total | B83: 4.0506329
A85: Which cities have the longest delivery time?
A87: Row Labels | B87: Sum of Delivery Time
A88: Mumbai | B88: 80
A89: Pune | B89: 51
A90: Somewhere | B90: 50
A91: Indore | B91: 45
A92: Bhopal | B92: 37
A93: Delhi | B93: 33
A94: Ahmedabad | B94: 24
A95: Grand Total | B95: 320

Sheet CUSTOMER & SEGMENT INSIGHTS
A1: Which segment (Consumer / Corporate / Home Office) generates the most revenue?
A3: Row Labels | B3: Sum of Total_Revenue
A4: Consumer | B4: 1674331
A5: Corporate | B5: 1330653
A6: Home Office | B6: 1148986
A7: Grand Total | B7: 4153970
A9: Which segment is most profitable?
A11: Row Labels | B11: Sum of Profit
A12: Consumer | B12: 1674329.4
A13: Corporate | B13: 1330650.9
A14: Home Office | B14: 1148984.4
A15: Grand Total | B15: 4153964.7
A17: What is the average order value per segment?
A19: Row Labels | B19: Avg_order_Value
A20: Consumer | B20: 72797
A21: Corporate | B21: 41582.906
A22: Home Office | B22: 47874.417
A23: Grand Total | B23: 52581.899
A25: Which customer segment receives maximum discounts?
A27: Row Labels | B27: Sum of Discount
A28: Corporate | B28: 0.39622642
A29: Home Office | B29: 0.31132075
A30: Consumer | B30: 0.29245283
A31: Grand Total | B31: 1
A33: What is the monthly sales trend?
A35: Row Labels | B35: Count of Order ID
A36: Jan | B36: 40
A37: Feb | B37: 37
A38: Mar | B38: 2
A39: Grand Total | B39: 79
A41: Here we can say that the jan is most saling month in the dataset
A43: Which month has the highest profit?
A45: Row Labels | B45: Sum of Profit
A46: Feb | B46: 2113207.6
A47: Jan | B47: 2040557
A48: Mar | B48: 200
A49: Grand Total | B49: 4153964.7
A51: Are there seasonal spikes in sales?
A53: Row Labels | B53: Count of Order ID
A54: Jan | B54: 40
...

Sheet 📈 TIME-BASED INSIGHTS
A1: What is the monthly sales trend?
A3: Row Labels | B3: Count of Order ID
A4: Jan | B4: 40
A5: Feb | B5: 37
A6: Mar | B6: 2
A7: Grand Total | B7: 79
A9: The above isnights are clearly indicated that there is peak sale in two months and very low in third one
A11: Which month has the highest profit?
A13: Row Labels | B13: Sum of Profit
A14: Jan | B14: 2040557
A15: Feb | B15: 2113207.6
A16: Mar | B16: 200
A17: Grand Total | B17: 4153964.7
A19: Here we can see that there is more profit in the feb months as compare to other months.

Sheet Misc
A1: Identify top 10% orders contributing to revenue (Pareto 80/20).
A3: Row Labels | B3: % of profit
A4: Grand Total | B4: 1
A5: CA-1094 | B5: 0.11650903
A6: CA-1012 | B6: 0.096041137
A7: CA-1005 | B7: 0.07385465
A8: CA-1009 | B8: 0.070152168
A9: CA-1023 | B9: 0.069107384
A10: CA-1082 | B10: 0.056839602
A11: CA-1004 | B11: 0.053404334
A12: CA-1051 | B12: 0.052482324
A13: CA-1098 | B13: 0.041177476
A14: CA-1092 | B14: 0.038513518
A15: CA-1019 | B15: 0.033223158
... A83: CA-1048 | B83: 0
A85: Which products should be discontinued due to losses?
A87: Row Labels | B87: Sum of Discount | C87: Sum of Profit
A88: CA-1048 | B88: 0.1 | C88: -0.1
A89: CA-1037 | B89: 0.1 | C89: -0.1
A90: CA-1041 | B90: 0.1 | C90: -0.1
A91: CA-1014 | B91: 0.1 | C91: -0.1
A92: CA-1050 | B92: 0.1 | C92: -0.1
A93: CA-1024 | B93: 0.1 | C93: -0.1
A94: CA-1053 | B94: 0.1 | C94: -0.1
A95: CA-1017 | B95: 0.1 | C95: -0.1
A96: CA-1059 | B96: 0.1 | C96: -0.1
A97: CA-1077 | B97: 0.1 | C97: -0.1
A98: CA-1066 | B98: 0.1 | C98: -0.1
A99: CA-1046 | B99: 0.05 | C99: -0.05
... A167: Grand Total | B167: 5.3 | C167: 4153964.7
A169: Thi is the list of the order id which are not profitable and should be discountuned after the losses

Sheet Dashboard
I2: Superstore -Analysis Report
A4: Row Labels | B4: Count of Order ID
A5: Jan | B5: 40
A6: Feb | B6: 37
A7: Mar | B7: 2
A8: Grand Total | B8: 79
